2025-09-18 23:28:08,057 - INFO - ==================================================
2025-09-18 23:28:08,058 - INFO - INICIANDO NUEVA EJECUCIÓN PARALELA (UNO A TODOS)
2025-09-18 23:28:08,058 - INFO - ==================================================
2025-09-18 23:28:08,060 - INFO - GDAL signalled an error: err_no=4, msg='G:\\LCP-parallel\\data\\points\\points.shp: No such file or directory'
2025-09-18 23:28:08,060 - ERROR - Error cargando puntos: Failed to open dataset (flags=68): G:\LCP-parallel\data\points\points.shp
2025-09-18 23:28:08,060 - CRITICAL - Error fatal en el proceso principal: No se pudieron cargar los puntos de entrada.
Traceback (most recent call last):
  File "C:\Users\Victor\AppData\Local\Temp\ipykernel_19768\3643645639.py", line 253, in <module>
    if not all_points: raise ValueError("No se pudieron cargar los puntos de entrada.")
                       ^^^^^^^^^^^^^^^^^^^^^^^^^^^^^^^^^^^^^^^^^^^^^^^^^^^^^^^^^^^^^^^^
ValueError: No se pudieron cargar los puntos de entrada.
2025-09-18 23:28:08,064 - INFO - ================== EJECUCIÓN FINALIZADA ==================


2025-09-18 23:28:29,031 - INFO - ==================================================
2025-09-18 23:28:29,031 - INFO - INICIANDO NUEVA EJECUCIÓN PARALELA (UNO A TODOS)
2025-09-18 23:28:29,031 - INFO - ==================================================
2025-09-18 23:28:29,049 - INFO - MODO NUEVO: Creando nueva sesión: 20250918_232829_desde_punto_0
2025-09-18 23:28:29,074 - INFO - Cargando datos compartidos (raster, máscara) a RAM...
2025-09-18 23:28:29,086 - INFO - Verificando puntos contra la máscara...
2025-09-18 23:28:29,087 - INFO - VERIFICACIÓN SUPERADA: Todos los puntos están dentro del área.
2025-09-18 23:28:29,088 - CRITICAL - Error fatal en el proceso principal: 'NoneType' object is not subscriptable
Traceback (most recent call last):
  File "C:\Users\Victor\AppData\Local\Temp\ipykernel_19768\661211730.py", line 293, in <module>
    start_pixel_hr = world_to_pixel(src.transform, origin_coords[0], origin_coords[1])
                                                   ~~~~~~~~~~~~~^^^
TypeError: 'NoneType' object is not subscriptable
2025-09-18 23:28:29,088 - INFO - ================== EJECUCIÓN FINALIZADA ==================


2025-09-18 23:28:57,369 - INFO - ==================================================
2025-09-18 23:28:57,369 - INFO - INICIANDO NUEVA EJECUCIÓN PARALELA (UNO A TODOS)
2025-09-18 23:28:57,369 - INFO - ==================================================
2025-09-18 23:28:57,373 - INFO - MODO REANUDACIÓN: Reanudando sesión incompleta '20250918_232829_desde_punto_0'.
2025-09-18 23:28:57,374 - INFO - GDAL signalled an error: err_no=4, msg='G:\\LCP-parallel\\data: Permission denied'
2025-09-18 23:28:57,374 - CRITICAL - Error fatal en el proceso principal: G:\LCP-parallel\data: Permission denied
Traceback (most recent call last):
  File "rasterio\\_base.pyx", line 310, in rasterio._base.DatasetBase.__init__
  File "rasterio\\_base.pyx", line 221, in rasterio._base.open_dataset
  File "rasterio\\_err.pyx", line 359, in rasterio._err.exc_wrap_pointer
rasterio._err.CPLE_OpenFailedError: G:\LCP-parallel\data: Permission denied

During handling of the above exception, another exception occurred:

Traceback (most recent call last):
  File "C:\Users\Victor\AppData\Local\Temp\ipykernel_19768\549320144.py", line 279, in <module>
    with rasterio.open(COST_RASTER_PATH) as src:
         ^^^^^^^^^^^^^^^^^^^^^^^^^^^^^^^
  File "G:\LCP-parallel\.venv\Lib\site-packages\rasterio\env.py", line 463, in wrapper
    return f(*args, **kwds)
           ^^^^^^^^^^^^^^^^
  File "G:\LCP-parallel\.venv\Lib\site-packages\rasterio\__init__.py", line 368, in open
    dataset = DatasetReader(path, driver=driver, sharing=sharing, **kwargs)
              ^^^^^^^^^^^^^^^^^^^^^^^^^^^^^^^^^^^^^^^^^^^^^^^^^^^^^^^^^^^^^
  File "rasterio\\_base.pyx", line 312, in rasterio._base.DatasetBase.__init__
rasterio.errors.RasterioIOError: G:\LCP-parallel\data: Permission denied
2025-09-18 23:28:57,376 - INFO - ================== EJECUCIÓN FINALIZADA ==================


2025-09-18 23:32:06,667 - INFO - ==================================================
2025-09-18 23:32:06,667 - INFO - INICIANDO NUEVA EJECUCIÓN PARALELA (UNO A TODOS)
2025-09-18 23:32:06,667 - INFO - ==================================================
2025-09-18 23:32:06,671 - INFO - MODO NUEVO: Creando nueva sesión: 20250918_233206_desde_punto_0
2025-09-18 23:32:06,674 - INFO - Cargando datos compartidos (raster, máscara) a RAM...
2025-09-18 23:32:06,685 - INFO - Verificando puntos contra la máscara...
2025-09-18 23:32:06,685 - INFO - VERIFICACIÓN SUPERADA: Todos los puntos están dentro del área.
2025-09-18 23:32:06,686 - CRITICAL - Error fatal en el proceso principal: 'NoneType' object is not subscriptable
Traceback (most recent call last):
  File "C:\Users\Victor\AppData\Local\Temp\ipykernel_19768\1615587618.py", line 285, in <module>
    start_pixel_hr = world_to_pixel(src.transform, origin_coords[0], origin_coords[1])
                                                   ~~~~~~~~~~~~~^^^
TypeError: 'NoneType' object is not subscriptable
2025-09-18 23:32:06,686 - INFO - ================== EJECUCIÓN FINALIZADA ==================


2025-09-18 23:34:51,307 - INFO - ==================================================
2025-09-18 23:34:51,307 - INFO - INICIANDO NUEVA EJECUCIÓN PARALELA (UNO A TODOS)
2025-09-18 23:34:51,307 - INFO - ==================================================
2025-09-18 23:34:51,311 - INFO - MODO REANUDACIÓN: Reanudando sesión incompleta '20250918_233206_desde_punto_0'.
2025-09-18 23:34:51,313 - INFO - Cargando datos compartidos (raster, máscara) a RAM...
2025-09-18 23:34:51,325 - INFO - Verificando puntos contra la máscara...
2025-09-18 23:34:51,325 - INFO - VERIFICACIÓN SUPERADA: Todos los puntos están dentro del área.
2025-09-18 23:34:51,325 - CRITICAL - ¡ANÁLISIS CANCELADO! El punto de origen con ID '0' no se encontró en el campo 'id' del shapefile.
2025-09-18 23:34:51,325 - CRITICAL - IDs disponibles: [1, 2, 3, 4, 5, 6, 7, 8, 9, 10, 11, 12, 13, 14]
2025-09-18 23:34:51,326 - CRITICAL - Error fatal en el proceso principal: 'NoneType' object is not subscriptable
Traceback (most recent call last):
  File "C:\Users\Victor\AppData\Local\Temp\ipykernel_19768\2515643348.py", line 262, in <module>
    start_pixel_hr = world_to_pixel(src.transform, origin_coords[0], origin_coords[1])
                                                   ~~~~~~~~~~~~~^^^
TypeError: 'NoneType' object is not subscriptable
2025-09-18 23:34:51,326 - INFO - ================== EJECUCIÓN FINALIZADA ==================


